<?xml version="1.0"?>

<sdf version='1.6'>
<!-- Basic model of the OpenASV -->
<!-- Based on OSRF WAM-V Model file -->
<model name="openasv">
  <static>false</static>
  <link name="base_link">
    <enable_wind>true</enable_wind>
    <inertial>
      <mass>10.5</mass>
      <inertia>
        <ixx>0.5</ixx>
        <ixy>0.0</ixy>
        <ixz>0.0</ixz>
        <iyy>1.0</iyy>
        <iyz>0.0</iyz>
        <izz>1.437</izz>
      </inertia>
    </inertial>

    <visual name="base_visual">
      <geometry>
        <mesh><uri>package://openasv_gz_description/models/openasv/meshes/openasv_base.dae</uri></mesh>
      </geometry>
    </visual>

    <!-- Top base -->
    <collision name="top_base">
      <pose>0 0 0.3 0 0 0</pose>
      <geometry>
        <box><size>0.4 0.25 0.16" </size></box>
      </geometry>
    </collision>

    <!-- left base -->
    <collision name="left_float">
      <pose>-0 0.28 -0.0 0 1.57 0 </pose>
      <geometry>
        <cylinder><length>1.24</length><radius>0.1</radius></cylinder>
      </geometry>
    </collision>

    <!-- right base -->
    <collision name="right_float">
      <pose>-0.0 -0.28 -0.0 0 1.57 0 </pose>
      <geometry>
        <cylinder><length>1.24</length><radius>0.1</radius></cylinder>
      </geometry>
    </collision>
  </link>

  <link name="left_propeller_link">
    <pose>-0.3 0.275 -0.144 0 0 0</pose>
    <visual name ="left_propeller_visual">
      <geometry>
        <mesh><uri>package://openasv_gz_description/models/openasv/meshes/propeller.dae</uri></mesh>
      </geometry>
    </visual>
    <collision name="left_propeller_collision">
      <pose>-0.0 0 0 0 1.57 0</pose>
      <geometry>
        <cylinder><length>0.10</length><radius>0.07</radius></cylinder>
      </geometry>
    </collision>
    <inertial>
      <mass>0.5</mass>
      <inertia>
        <ixx>0.0000044</ixx>
        <ixy>0.0</ixy>
        <ixz>0.0</ixz>
        <iyy>0.0000035</iyy>
        <iyz>0.0</iyz>
        <izz>0.0000018</izz>
      </inertia>
    </inertial>
  </link>

  <joint name="left_engine_propeller_joint" type="revolute">
    <axis>
      <xyz>1 0 0</xyz>
      <limit>
        <effort>100</effort>
        <velocity>100</velocity>
      </limit>
      <dynamics>
        <friction>0.05</friction>
        <damping>0.05</damping>
      </dynamics>
    </axis>
    <parent>base_link</parent>
    <child>left_propeller_link</child>
  </joint>

  <link name="right_propeller_link">
    <pose>-0.3 -0.275 -0.144 0 0 0</pose>
    <visual name ="right_propeller_visual">
      <geometry>
        <mesh><uri>package://openasv_gz_description/models/openasv/meshes/propeller.dae</uri></mesh>
      </geometry>
    </visual>
    <collision name="right_propeller_collision">
      <pose>-0.0 0 0 0 1.57 0</pose>
      <geometry>
        <cylinder><length>0.10</length><radius>0.07</radius></cylinder>
      </geometry>
    </collision>
    <inertial>
      <mass>0.011</mass>
      <inertia>
        <ixx>0.0000044</ixx>
        <ixy>0.0</ixy>
        <ixz>0.0</ixz>
        <iyy>0.0000035</iyy>
        <iyz>0.0</iyz>
        <izz>0.0000018</izz>
      </inertia>
    </inertial>
  </link>

  <joint name="right_engine_propeller_joint" type="revolute">
    <axis>
      <xyz>1 0 0</xyz>
      <limit>
        <effort>100</effort>
        <velocity>100</velocity>
      </limit>
      <dynamics>
        <friction>0.05</friction>
        <damping>0.05</damping>
      </dynamics>
    </axis>
    <parent>base_link</parent>
    <child>right_propeller_link</child>
  </joint>

  <!-- Uncomment to enable the left thruster -->
    <plugin
      filename="gz-sim-thruster-system"
      name="gz::sim::systems::Thruster">
      <joint_name>left_engine_propeller_joint</joint_name>
      <thrust_coefficient>0.000085</thrust_coefficient>
      <fluid_density>1000</fluid_density>
      <propeller_diameter>0.1</propeller_diameter>
      <velocity_control>true</velocity_control>
    </plugin>

  <!-- Uncomment to enable the right thruster -->
    <plugin
      filename="gz-sim-thruster-system"
      name="gz::sim::systems::Thruster">
      <joint_name>right_engine_propeller_joint</joint_name>
      <thrust_coefficient>0.000085</thrust_coefficient>
      <fluid_density>1000</fluid_density>
      <propeller_diameter>0.1</propeller_diameter>
      <velocity_control>true</velocity_control>
    </plugin>

  <!-- Uncomment to produce buoyancy on the left hull -->
  <plugin
    filename="libSurface.so"
    name="maritime::Surface">
    <link_name>base_link</link_name>
    <hull_length>1.24</hull_length>
    <hull_radius>0.08</hull_radius>
    <fluid_level>0.1</fluid_level>
    <points>
      <point>0.42 0.28 0</point>
      <point>-0.42 0.28 0</point>
    </points>
    <wavefield>
      <topic>/gazebo/wavefield/parameters</topic>
    </wavefield>
  </plugin>

  <!-- Uncomment to produce buoyancy on the right hull -->
  <plugin
    filename="libSurface.so"
    name="maritime::Surface">
    <link_name>base_link</link_name>
    <hull_length>1.24</hull_length>
    <hull_radius>0.08</hull_radius>
    <fluid_level>0.1</fluid_level>
    <points>
      <point>0.42 -0.28 0</point>
      <point>-0.42 -0.28 0</point>
    </points>
    <wavefield>
      <topic>/gazebo/wavefield/parameters</topic>
    </wavefield>
  </plugin>

  <!-- Uncomment to enable hydrodynamics -->
  <plugin
    filename="gz-sim-hydrodynamics-system"
    name="gz::sim::systems::Hydrodynamics">
    <link_name>base_link</link_name>
    <!--Added Mass Terms-->
    <nDotV>  -4.5239 </nDotV> 
    <nDotR>  -0.8704 </nDotR> 
    <xDotU>  -0.7875 </xDotU> 
    <yDotR>  -0.3619 </yDotR> 
    <yDotV>  -5.4287 </yDotV>
    <!--Linear Drag Terms--> 
    <xU>      0.4570 </xU>    
    <yV>	 -329.0  </yV>	
    <nR>	 -0.2147 </nR>	
    <nV>	 -0.5368 </nV>	
    <yR>	 -53.68  </yR>	
    <!--Quadratic Drag Terms--> 
    <xUabsU> -6.9686 </xUabsU>
    <yVabsV> -52.8   </yVabsV>
    <yVabsR>  0.0    </yVabsR>
    <yRabsV>  0.0    </yRabsV>
    <yRabsR> -6.3360 </yRabsR>
    <nVabsV>  0.0    </nVabsV>
    <nVabsR> -6.3360 </nVabsR>
    <nRabsV> -6.3360 </nRabsV>
    <nRabsR> -2.8512 </nRabsR>
    <!--Below terms are added from Roboboat01 model for damping in z, roll and pitch in Gazebo-->
    <kP>-12.0</kP>
    <kPP>-24.0</kPP>
    <mQ>-36.0</mQ>
    <mQQ>-35.0</mQQ>
    <zW>-20.0</zW>
  </plugin> 
  <plugin
        filename="gz-sim-joint-state-publisher-system"
        name="gz::sim::systems::JointStatePublisher">
  </plugin>
      <plugin
        filename="gz-sim-pose-publisher-system"
        name="gz::sim::systems::PosePublisher">
        <publish_link_pose>true</publish_link_pose>
        <use_pose_vector_msg>true</use_pose_vector_msg>
        <static_publisher>true</static_publisher>
        <static_update_frequency>1</static_update_frequency>
    </plugin>
    <plugin
        filename="gz-sim-odometry-publisher-system"
        name="gz::sim::systems::OdometryPublisher">
        <odom_frame>openasv</odom_frame>
        <robot_base_frame>openasv</robot_base_frame>
    </plugin>

</model>

</sdf>
